
  0%|                                                     | 0/5 [00:00<?, ?it/s]
BasicUNet features: (64, 128, 256, 512, 1024, 64).
  0%|                                                     | 0/5 [00:00<?, ?it/s]Process wandb_internal:
Traceback (most recent call last):
  File "/Users/wangyangwu/miniforge3/envs/maastro/lib/python3.9/site-packages/wandb/sdk/internal/internal.py", line 146, in wandb_internal
    time.sleep(1)
KeyboardInterrupt
During handling of the above exception, another exception occurred:
Traceback (most recent call last):
  File "/Users/wangyangwu/miniforge3/envs/maastro/lib/python3.9/multiprocessing/process.py", line 315, in _bootstrap
    self.run()
  File "/Users/wangyangwu/miniforge3/envs/maastro/lib/python3.9/multiprocessing/process.py", line 108, in run
    self._target(*self._args, **self._kwargs)
  File "/Users/wangyangwu/miniforge3/envs/maastro/lib/python3.9/site-packages/wandb/sdk/internal/internal.py", line 152, in wandb_internal
    logger.warning("Internal process interrupt: {}".format(interrupt_count))
  File "/Users/wangyangwu/miniforge3/envs/maastro/lib/python3.9/logging/__init__.py", line 1458, in warning
    self._log(WARNING, msg, args, **kwargs)
  File "/Users/wangyangwu/miniforge3/envs/maastro/lib/python3.9/logging/__init__.py", line 1589, in _log
    self.handle(record)
  File "/Users/wangyangwu/miniforge3/envs/maastro/lib/python3.9/logging/__init__.py", line 1599, in handle
    self.callHandlers(record)
  File "/Users/wangyangwu/miniforge3/envs/maastro/lib/python3.9/logging/__init__.py", line 1661, in callHandlers
    hdlr.handle(record)
  File "/Users/wangyangwu/miniforge3/envs/maastro/lib/python3.9/logging/__init__.py", line 952, in handle
    self.emit(record)
  File "/Users/wangyangwu/miniforge3/envs/maastro/lib/python3.9/logging/__init__.py", line 1187, in emit
    StreamHandler.emit(self, record)
  File "/Users/wangyangwu/miniforge3/envs/maastro/lib/python3.9/logging/__init__.py", line 1087, in emit
    self.flush()
  File "/Users/wangyangwu/miniforge3/envs/maastro/lib/python3.9/logging/__init__.py", line 1067, in flush
    self.stream.flush()
