2022-02-21 21:35:07,207 INFO    MainThread:11594 [internal.py:wandb_internal():89] W&B internal server running at pid: 11594, started at: 2022-02-21 21:35:07.207166
2022-02-21 21:35:07,207 INFO    WriterThread:11594 [datastore.py:open_for_write():77] open: /Users/wangyangwu/Documents/Maastro/NeuralNets/BasicUNet/wandb/run-20220221_213506-1vv0hlij/run-1vv0hlij.wandb
2022-02-21 21:35:07,208 DEBUG   HandlerThread:11594 [handler.py:handle_request():131] handle_request: check_version
2022-02-21 21:35:07,208 DEBUG   SenderThread:11594 [sender.py:send():235] send: header
2022-02-21 21:35:07,208 DEBUG   SenderThread:11594 [sender.py:send_request():249] send_request: check_version
2022-02-21 21:35:07,211 DEBUG   SenderThread:11594 [sender.py:send():235] send: run
2022-02-21 21:35:10,841 ERROR   SenderThread:11594 [retry.py:__call__():126] Retry attempt failed:
Traceback (most recent call last):
  File "/Users/wangyangwu/miniforge3/envs/maastro/lib/python3.9/site-packages/urllib3/connection.py", line 174, in _new_conn
    conn = connection.create_connection(
  File "/Users/wangyangwu/miniforge3/envs/maastro/lib/python3.9/site-packages/urllib3/util/connection.py", line 72, in create_connection
    for res in socket.getaddrinfo(host, port, family, socket.SOCK_STREAM):
  File "/Users/wangyangwu/miniforge3/envs/maastro/lib/python3.9/socket.py", line 954, in getaddrinfo
    for res in _socket.getaddrinfo(host, port, family, type, proto, flags):
socket.gaierror: [Errno 8] nodename nor servname provided, or not known

During handling of the above exception, another exception occurred:

Traceback (most recent call last):
  File "/Users/wangyangwu/miniforge3/envs/maastro/lib/python3.9/site-packages/urllib3/connectionpool.py", line 703, in urlopen
    httplib_response = self._make_request(
  File "/Users/wangyangwu/miniforge3/envs/maastro/lib/python3.9/site-packages/urllib3/connectionpool.py", line 386, in _make_request
    self._validate_conn(conn)
  File "/Users/wangyangwu/miniforge3/envs/maastro/lib/python3.9/site-packages/urllib3/connectionpool.py", line 1040, in _validate_conn
    conn.connect()
  File "/Users/wangyangwu/miniforge3/envs/maastro/lib/python3.9/site-packages/urllib3/connection.py", line 358, in connect
    conn = self._new_conn()
  File "/Users/wangyangwu/miniforge3/envs/maastro/lib/python3.9/site-packages/urllib3/connection.py", line 186, in _new_conn
    raise NewConnectionError(
urllib3.exceptions.NewConnectionError: <urllib3.connection.HTTPSConnection object at 0x114d71130>: Failed to establish a new connection: [Errno 8] nodename nor servname provided, or not known

During handling of the above exception, another exception occurred:

Traceback (most recent call last):
  File "/Users/wangyangwu/miniforge3/envs/maastro/lib/python3.9/site-packages/requests/adapters.py", line 440, in send
    resp = conn.urlopen(
  File "/Users/wangyangwu/miniforge3/envs/maastro/lib/python3.9/site-packages/urllib3/connectionpool.py", line 785, in urlopen
    retries = retries.increment(
  File "/Users/wangyangwu/miniforge3/envs/maastro/lib/python3.9/site-packages/urllib3/util/retry.py", line 592, in increment
    raise MaxRetryError(_pool, url, error or ResponseError(cause))
urllib3.exceptions.MaxRetryError: HTTPSConnectionPool(host='api.wandb.ai', port=443): Max retries exceeded with url: /graphql (Caused by NewConnectionError('<urllib3.connection.HTTPSConnection object at 0x114d71130>: Failed to establish a new connection: [Errno 8] nodename nor servname provided, or not known'))

During handling of the above exception, another exception occurred:

Traceback (most recent call last):
  File "/Users/wangyangwu/miniforge3/envs/maastro/lib/python3.9/site-packages/wandb/sdk/lib/retry.py", line 102, in __call__
    result = self._call_fn(*args, **kwargs)
  File "/Users/wangyangwu/miniforge3/envs/maastro/lib/python3.9/site-packages/wandb/sdk/internal/internal_api.py", line 140, in execute
    return self.client.execute(*args, **kwargs)
  File "/Users/wangyangwu/miniforge3/envs/maastro/lib/python3.9/site-packages/wandb/vendor/gql-0.2.0/gql/client.py", line 52, in execute
    result = self._get_result(document, *args, **kwargs)
  File "/Users/wangyangwu/miniforge3/envs/maastro/lib/python3.9/site-packages/wandb/vendor/gql-0.2.0/gql/client.py", line 60, in _get_result
    return self.transport.execute(document, *args, **kwargs)
  File "/Users/wangyangwu/miniforge3/envs/maastro/lib/python3.9/site-packages/wandb/vendor/gql-0.2.0/gql/transport/requests.py", line 38, in execute
    request = requests.post(self.url, **post_args)
  File "/Users/wangyangwu/miniforge3/envs/maastro/lib/python3.9/site-packages/requests/api.py", line 117, in post
    return request('post', url, data=data, json=json, **kwargs)
  File "/Users/wangyangwu/miniforge3/envs/maastro/lib/python3.9/site-packages/requests/api.py", line 61, in request
    return session.request(method=method, url=url, **kwargs)
  File "/Users/wangyangwu/miniforge3/envs/maastro/lib/python3.9/site-packages/requests/sessions.py", line 529, in request
    resp = self.send(prep, **send_kwargs)
  File "/Users/wangyangwu/miniforge3/envs/maastro/lib/python3.9/site-packages/requests/sessions.py", line 645, in send
    r = adapter.send(request, **kwargs)
  File "/Users/wangyangwu/miniforge3/envs/maastro/lib/python3.9/site-packages/requests/adapters.py", line 519, in send
    raise ConnectionError(e, request=request)
requests.exceptions.ConnectionError: HTTPSConnectionPool(host='api.wandb.ai', port=443): Max retries exceeded with url: /graphql (Caused by NewConnectionError('<urllib3.connection.HTTPSConnection object at 0x114d71130>: Failed to establish a new connection: [Errno 8] nodename nor servname provided, or not known'))
2022-02-21 21:35:19,195 WARNING MainThread:11594 [internal.py:wandb_internal():152] Internal process interrupt: 1
2022-02-21 21:35:25,217 WARNING MainThread:11594 [internal.py:is_dead():380] Internal process exiting, parent pid 11576 disappeared
2022-02-21 21:35:25,217 ERROR   MainThread:11594 [internal.py:wandb_internal():148] Internal process shutdown.
2022-02-21 21:35:25,231 INFO    HandlerThread:11594 [handler.py:finish():739] shutting down handler
2022-02-21 21:35:25,277 INFO    WriterThread:11594 [datastore.py:close():281] close: /Users/wangyangwu/Documents/Maastro/NeuralNets/BasicUNet/wandb/run-20220221_213506-1vv0hlij/run-1vv0hlij.wandb
2022-02-21 21:35:26,596 INFO    SenderThread:11594 [dir_watcher.py:__init__():169] watching files in: /Users/wangyangwu/Documents/Maastro/NeuralNets/BasicUNet/wandb/run-20220221_213506-1vv0hlij/files
2022-02-21 21:35:26,596 INFO    SenderThread:11594 [sender.py:_start_run_threads():809] run started: 1vv0hlij with start time 1645475706
2022-02-21 21:35:26,596 INFO    SenderThread:11594 [sender.py:finish():1075] shutting down sender
2022-02-21 21:35:26,596 INFO    SenderThread:11594 [dir_watcher.py:finish():283] shutting down directory watcher
2022-02-21 21:35:27,599 INFO    SenderThread:11594 [dir_watcher.py:finish():313] scan: /Users/wangyangwu/Documents/Maastro/NeuralNets/BasicUNet/wandb/run-20220221_213506-1vv0hlij/files
2022-02-21 21:35:27,600 INFO    SenderThread:11594 [dir_watcher.py:finish():327] scan save: /Users/wangyangwu/Documents/Maastro/NeuralNets/BasicUNet/wandb/run-20220221_213506-1vv0hlij/files/config.yaml config.yaml
2022-02-21 21:35:27,600 INFO    SenderThread:11594 [file_pusher.py:finish():177] shutting down file pusher
2022-02-21 21:35:27,603 INFO    SenderThread:11594 [file_pusher.py:join():182] waiting for file pusher
2022-02-21 21:35:30,693 INFO    Thread-10 :11594 [upload_job.py:push():137] Uploaded file /Users/wangyangwu/Documents/Maastro/NeuralNets/BasicUNet/wandb/run-20220221_213506-1vv0hlij/files/config.yaml
2022-02-21 21:35:31,458 INFO    MainThread:11594 [internal.py:handle_exit():79] Internal process exited
